20/Feb/2020 18:13 [Thread-1: 20520]C:\Users\Administrator\PycharmProjects\riskcontrol\aaa\fin_renhang_riskcontrol\akamx\views.py:post:53 INFO - 开始时间3.2740335
20/Feb/2020 18:13 [Thread-1: 20520]C:\Users\Administrator\PycharmProjects\riskcontrol\aaa\fin_renhang_riskcontrol\akamx\views.py:post:78 INFO - requests时间3.275605
20/Feb/2020 18:13 [Thread-1: 20520]C:\Users\Administrator\PycharmProjects\riskcontrol\aaa\fin_renhang_riskcontrol\akamx\views.py:post:82 INFO - 获取客户的时间3.2760994
20/Feb/2020 18:13 [Thread-1: 20520]C:\Users\Administrator\PycharmProjects\riskcontrol\aaa\fin_renhang_riskcontrol\akamx\views.py:post:90 INFO - 保存客户的时间3.3288112
20/Feb/2020 18:13 [Thread-1: 20520]C:\Users\Administrator\PycharmProjects\riskcontrol\aaa\fin_renhang_riskcontrol\akamx\views.py:post:97 INFO - 获取人行的数据3.3291648
20/Feb/2020 18:13 [Thread-1: 20520]C:\Users\Administrator\PycharmProjects\riskcontrol\aaa\fin_renhang_riskcontrol\akamx\views.py:post:104 INFO - 获取三方数据4.6250914
20/Feb/2020 18:13 [Thread-1: 20520]C:\ProgramData\Anaconda3\lib\site-packages\django\core\handlers\exception.py:handle_uncaught_exception:118 ERROR - Internal Server Error: /api/
Traceback (most recent call last):
  File "C:\ProgramData\Anaconda3\lib\site-packages\django\core\handlers\exception.py", line 35, in inner
    response = get_response(request)
  File "C:\ProgramData\Anaconda3\lib\site-packages\django\core\handlers\base.py", line 128, in _get_response
    response = self.process_exception_by_middleware(e, request)
  File "C:\ProgramData\Anaconda3\lib\site-packages\django\core\handlers\base.py", line 126, in _get_response
    response = wrapped_callback(request, *callback_args, **callback_kwargs)
  File "C:\ProgramData\Anaconda3\lib\site-packages\django\views\decorators\csrf.py", line 54, in wrapped_view
    return view_func(*args, **kwargs)
  File "C:\ProgramData\Anaconda3\lib\site-packages\django\views\generic\base.py", line 69, in view
    return self.dispatch(request, *args, **kwargs)
  File "C:\ProgramData\Anaconda3\lib\site-packages\rest_framework\views.py", line 505, in dispatch
    response = self.handle_exception(exc)
  File "C:\ProgramData\Anaconda3\lib\site-packages\rest_framework\views.py", line 465, in handle_exception
    self.raise_uncaught_exception(exc)
  File "C:\ProgramData\Anaconda3\lib\site-packages\rest_framework\views.py", line 476, in raise_uncaught_exception
    raise exc
  File "C:\ProgramData\Anaconda3\lib\site-packages\rest_framework\views.py", line 502, in dispatch
    response = handler(request, *args, **kwargs)
  File "C:\Users\Administrator\PycharmProjects\riskcontrol\aaa\fin_renhang_riskcontrol\akamx\views.py", line 143, in post
    dict_strategy_group, dict_strategy_group_br= tongdun_cl.all_cl()
  File "C:\Users\Administrator\PycharmProjects\riskcontrol\aaa\fin_renhang_riskcontrol\akamx\bairongcelv.py", line 344, in all_cl
    td_cl = self.td_cl(td_dict)
  File "C:\Users\Administrator\PycharmProjects\riskcontrol\aaa\fin_renhang_riskcontrol\akamx\bairongcelv.py", line 325, in td_cl
    if dict_moxing['success']:
TypeError: 'NoneType' object is not subscriptable
20/Feb/2020 18:13 [Thread-1: 20520]C:\ProgramData\Anaconda3\lib\site-packages\django\core\servers\basehttp.py:log_message:124 ERROR - "POST /api/ HTTP/1.1" 500 17102
20/Feb/2020 18:13 [Thread-1: 19240]C:\Users\Administrator\PycharmProjects\riskcontrol\aaa\fin_renhang_riskcontrol\akamx\views.py:post:53 INFO - 开始时间6.6114357
20/Feb/2020 18:13 [Thread-1: 19240]C:\Users\Administrator\PycharmProjects\riskcontrol\aaa\fin_renhang_riskcontrol\akamx\views.py:post:78 INFO - requests时间6.6117957
20/Feb/2020 18:13 [Thread-1: 19240]C:\Users\Administrator\PycharmProjects\riskcontrol\aaa\fin_renhang_riskcontrol\akamx\views.py:post:82 INFO - 获取客户的时间6.6121147
20/Feb/2020 18:13 [Thread-1: 19240]C:\Users\Administrator\PycharmProjects\riskcontrol\aaa\fin_renhang_riskcontrol\akamx\views.py:post:90 INFO - 保存客户的时间6.6676399
20/Feb/2020 18:13 [Thread-1: 19240]C:\Users\Administrator\PycharmProjects\riskcontrol\aaa\fin_renhang_riskcontrol\akamx\views.py:post:97 INFO - 获取人行的数据6.6680355
20/Feb/2020 18:13 [Thread-1: 19240]C:\Users\Administrator\PycharmProjects\riskcontrol\aaa\fin_renhang_riskcontrol\akamx\views.py:post:104 INFO - 获取三方数据7.955733
20/Feb/2020 18:13 [Thread-1: 19240]C:\ProgramData\Anaconda3\lib\site-packages\django\core\handlers\exception.py:handle_uncaught_exception:118 ERROR - Internal Server Error: /api/
Traceback (most recent call last):
  File "C:\ProgramData\Anaconda3\lib\site-packages\django\core\handlers\exception.py", line 35, in inner
    response = get_response(request)
  File "C:\ProgramData\Anaconda3\lib\site-packages\django\core\handlers\base.py", line 128, in _get_response
    response = self.process_exception_by_middleware(e, request)
  File "C:\ProgramData\Anaconda3\lib\site-packages\django\core\handlers\base.py", line 126, in _get_response
    response = wrapped_callback(request, *callback_args, **callback_kwargs)
  File "C:\ProgramData\Anaconda3\lib\site-packages\django\views\decorators\csrf.py", line 54, in wrapped_view
    return view_func(*args, **kwargs)
  File "C:\ProgramData\Anaconda3\lib\site-packages\django\views\generic\base.py", line 69, in view
    return self.dispatch(request, *args, **kwargs)
  File "C:\ProgramData\Anaconda3\lib\site-packages\rest_framework\views.py", line 505, in dispatch
    response = self.handle_exception(exc)
  File "C:\ProgramData\Anaconda3\lib\site-packages\rest_framework\views.py", line 465, in handle_exception
    self.raise_uncaught_exception(exc)
  File "C:\ProgramData\Anaconda3\lib\site-packages\rest_framework\views.py", line 476, in raise_uncaught_exception
    raise exc
  File "C:\ProgramData\Anaconda3\lib\site-packages\rest_framework\views.py", line 502, in dispatch
    response = handler(request, *args, **kwargs)
  File "C:\Users\Administrator\PycharmProjects\riskcontrol\aaa\fin_renhang_riskcontrol\akamx\views.py", line 143, in post
    dict_strategy_group, dict_strategy_group_br= tongdun_cl.all_cl()
  File "C:\Users\Administrator\PycharmProjects\riskcontrol\aaa\fin_renhang_riskcontrol\akamx\bairongcelv.py", line 344, in all_cl
    td_cl = self.td_cl(td_dict)
  File "C:\Users\Administrator\PycharmProjects\riskcontrol\aaa\fin_renhang_riskcontrol\akamx\bairongcelv.py", line 325, in td_cl
    if dict_moxing['success']:
TypeError: 'NoneType' object is not subscriptable
20/Feb/2020 18:13 [Thread-1: 19240]C:\ProgramData\Anaconda3\lib\site-packages\django\core\servers\basehttp.py:log_message:124 ERROR - "POST /api/ HTTP/1.1" 500 17102
