20/Feb/2020 12:49 [Thread-1: 12000]C:\Users\Administrator\PycharmProjects\riskcontrol\aaa\fin_renhang_riskcontrol\akamx\views.py:post:53 INFO - 开始时间8.7995733
20/Feb/2020 12:49 [Thread-1: 12000]C:\Users\Administrator\PycharmProjects\riskcontrol\aaa\fin_renhang_riskcontrol\akamx\views.py:post:78 INFO - requests时间8.8010112
20/Feb/2020 12:49 [Thread-1: 12000]C:\Users\Administrator\PycharmProjects\riskcontrol\aaa\fin_renhang_riskcontrol\akamx\views.py:post:82 INFO - 获取客户的时间8.8013852
20/Feb/2020 12:49 [Thread-1: 12000]C:\Users\Administrator\PycharmProjects\riskcontrol\aaa\fin_renhang_riskcontrol\akamx\views.py:post:90 INFO - 保存客户的时间8.8479953
20/Feb/2020 12:49 [Thread-1: 12000]C:\Users\Administrator\PycharmProjects\riskcontrol\aaa\fin_renhang_riskcontrol\akamx\views.py:post:97 INFO - 获取人行的数据8.8483403
20/Feb/2020 12:49 [Thread-1: 12000]C:\ProgramData\Anaconda3\lib\site-packages\django\core\handlers\exception.py:handle_uncaught_exception:118 ERROR - Internal Server Error: /api/
Traceback (most recent call last):
  File "C:\ProgramData\Anaconda3\lib\site-packages\django\core\handlers\exception.py", line 35, in inner
    response = get_response(request)
  File "C:\ProgramData\Anaconda3\lib\site-packages\django\core\handlers\base.py", line 128, in _get_response
    response = self.process_exception_by_middleware(e, request)
  File "C:\ProgramData\Anaconda3\lib\site-packages\django\core\handlers\base.py", line 126, in _get_response
    response = wrapped_callback(request, *callback_args, **callback_kwargs)
  File "C:\ProgramData\Anaconda3\lib\site-packages\django\views\decorators\csrf.py", line 54, in wrapped_view
    return view_func(*args, **kwargs)
  File "C:\ProgramData\Anaconda3\lib\site-packages\django\views\generic\base.py", line 69, in view
    return self.dispatch(request, *args, **kwargs)
  File "C:\ProgramData\Anaconda3\lib\site-packages\rest_framework\views.py", line 505, in dispatch
    response = self.handle_exception(exc)
  File "C:\ProgramData\Anaconda3\lib\site-packages\rest_framework\views.py", line 465, in handle_exception
    self.raise_uncaught_exception(exc)
  File "C:\ProgramData\Anaconda3\lib\site-packages\rest_framework\views.py", line 476, in raise_uncaught_exception
    raise exc
  File "C:\ProgramData\Anaconda3\lib\site-packages\rest_framework\views.py", line 502, in dispatch
    response = handler(request, *args, **kwargs)
  File "C:\Users\Administrator\PycharmProjects\riskcontrol\aaa\fin_renhang_riskcontrol\akamx\views.py", line 101, in post
    bl_json = bairong.moxing_tz()
  File "C:\Users\Administrator\PycharmProjects\riskcontrol\aaa\fin_renhang_riskcontrol\akamx\bairong.py", line 274, in moxing_tz
    print('eeeeeeeeeeeeeeee',df_all[feature])
  File "C:\ProgramData\Anaconda3\lib\site-packages\pandas\core\frame.py", line 2934, in __getitem__
    raise_missing=True)
  File "C:\ProgramData\Anaconda3\lib\site-packages\pandas\core\indexing.py", line 1354, in _convert_to_indexer
    return self._get_listlike_indexer(obj, axis, **kwargs)[1]
  File "C:\ProgramData\Anaconda3\lib\site-packages\pandas\core\indexing.py", line 1161, in _get_listlike_indexer
    raise_missing=raise_missing)
  File "C:\ProgramData\Anaconda3\lib\site-packages\pandas\core\indexing.py", line 1252, in _validate_read_indexer
    raise KeyError("{} not in index".format(not_found))
KeyError: "['flag_applyloanusury', 'als_m6_id_bank_min_inteday', 'd15', 'b2', 'als_m12_cell_bank_tra_allnum', 'b26', 'als_m12_id_bank_tra_allnum', 'als_m6_cell_bank_tra_orgnum', 'a86', 'd40', 'cell_city_ec_level', 'b20', 'b14'] not in index"
20/Feb/2020 12:49 [Thread-1: 12000]C:\ProgramData\Anaconda3\lib\site-packages\django\core\servers\basehttp.py:log_message:124 ERROR - "POST /api/ HTTP/1.1" 500 17997
