19/Feb/2020 10:54 [Thread-4: 14788]C:\Users\Administrator\PycharmProjects\riskcontrol\aaa\fin_renhang_riskcontrol\akamx\views.py:post:53 INFO - 开始时间2911.071275
19/Feb/2020 10:54 [Thread-4: 14788]C:\Users\Administrator\PycharmProjects\riskcontrol\aaa\fin_renhang_riskcontrol\akamx\views.py:post:78 INFO - requests时间2911.0752967
19/Feb/2020 10:54 [Thread-4: 14788]C:\Users\Administrator\PycharmProjects\riskcontrol\aaa\fin_renhang_riskcontrol\akamx\views.py:post:82 INFO - 获取客户的时间2911.0763466
19/Feb/2020 10:54 [Thread-4: 14788]C:\Users\Administrator\PycharmProjects\riskcontrol\aaa\fin_renhang_riskcontrol\akamx\views.py:post:90 INFO - 保存客户的时间2911.1394865
19/Feb/2020 10:54 [Thread-4: 14788]C:\Users\Administrator\PycharmProjects\riskcontrol\aaa\fin_renhang_riskcontrol\akamx\views.py:post:97 INFO - 获取人行的数据2911.1398757
19/Feb/2020 10:54 [Thread-4: 14788]C:\Users\Administrator\PycharmProjects\riskcontrol\aaa\fin_renhang_riskcontrol\akamx\views.py:post:103 INFO - 获取三方数据2912.3814594
19/Feb/2020 10:54 [Thread-4: 14788]C:\Users\Administrator\PycharmProjects\riskcontrol\aaa\fin_renhang_riskcontrol\akamx\views.py:post:161 INFO - 输出最终数据2913.4142658
19/Feb/2020 10:54 [Thread-4: 14788]C:\Users\Administrator\PycharmProjects\riskcontrol\aaa\fin_renhang_riskcontrol\akamx\views.py:post:171 INFO - 保存数据2913.4363019
19/Feb/2020 10:54 [Thread-4: 14788]C:\Users\Administrator\PycharmProjects\riskcontrol\aaa\fin_renhang_riskcontrol\akamx\views.py:post:187 INFO - 结束时间2913.4366308
19/Feb/2020 10:54 [Thread-4: 14788]C:\Users\Administrator\PycharmProjects\riskcontrol\aaa\fin_renhang_riskcontrol\akamx\views.py:post:189 INFO - 总共用时间是2.3653558000000885
19/Feb/2020 10:54 [Thread-4: 14788]C:\ProgramData\Anaconda3\lib\site-packages\django\core\servers\basehttp.py:log_message:124 INFO - "POST /api/ HTTP/1.1" 200 15
19/Feb/2020 10:55 [Thread-1: 20324]C:\Users\Administrator\PycharmProjects\riskcontrol\aaa\fin_renhang_riskcontrol\akamx\views.py:post:53 INFO - 开始时间7.1759569
19/Feb/2020 10:55 [Thread-1: 20324]C:\Users\Administrator\PycharmProjects\riskcontrol\aaa\fin_renhang_riskcontrol\akamx\views.py:post:78 INFO - requests时间7.1763651
19/Feb/2020 10:55 [Thread-1: 20324]C:\Users\Administrator\PycharmProjects\riskcontrol\aaa\fin_renhang_riskcontrol\akamx\views.py:post:82 INFO - 获取客户的时间7.1766921
19/Feb/2020 10:55 [Thread-1: 20324]C:\Users\Administrator\PycharmProjects\riskcontrol\aaa\fin_renhang_riskcontrol\akamx\views.py:post:90 INFO - 保存客户的时间7.2297901
19/Feb/2020 10:55 [Thread-1: 20324]C:\Users\Administrator\PycharmProjects\riskcontrol\aaa\fin_renhang_riskcontrol\akamx\views.py:post:97 INFO - 获取人行的数据7.2301332
19/Feb/2020 10:55 [Thread-1: 20324]C:\ProgramData\Anaconda3\lib\site-packages\django\core\handlers\exception.py:handle_uncaught_exception:118 ERROR - Internal Server Error: /api/
Traceback (most recent call last):
  File "C:\Users\Administrator\PycharmProjects\riskcontrol\aaa\fin_renhang_riskcontrol\akamx\views.py", line 101, in post
    bl_json = bairong.moxing_tz()
  File "C:\Users\Administrator\PycharmProjects\riskcontrol\aaa\fin_renhang_riskcontrol\akamx\bairong.py", line 240, in moxing_tz
    p = xgb.predict_proba(df_all[feature])[:, 1]
  File "C:\ProgramData\Anaconda3\lib\site-packages\pandas\core\frame.py", line 2934, in __getitem__
    raise_missing=True)
  File "C:\ProgramData\Anaconda3\lib\site-packages\pandas\core\indexing.py", line 1354, in _convert_to_indexer
    return self._get_listlike_indexer(obj, axis, **kwargs)[1]
  File "C:\ProgramData\Anaconda3\lib\site-packages\pandas\core\indexing.py", line 1161, in _get_listlike_indexer
    raise_missing=raise_missing)
  File "C:\ProgramData\Anaconda3\lib\site-packages\pandas\core\indexing.py", line 1252, in _validate_read_indexer
    raise KeyError("{} not in index".format(not_found))
KeyError: "['als_m6_cell_bank_tra_orgnum', 'als_m12_cell_bank_tra_allnum', 'cell_province', 'b20', 'b14', 'als_m6_id_bank_min_inteday', 'cell_city_ec_level', 'b2', 'apply_age', 'als_m12_id_bank_tra_allnum', 'gender', 'id_city', 'flag_applyloanusury', 'd40', 'd15', 'b26', 'a86', 'cell_city'] not in index"

During handling of the above exception, another exception occurred:

Traceback (most recent call last):
  File "C:\ProgramData\Anaconda3\lib\site-packages\django\core\handlers\exception.py", line 35, in inner
    response = get_response(request)
  File "C:\ProgramData\Anaconda3\lib\site-packages\django\core\handlers\base.py", line 128, in _get_response
    response = self.process_exception_by_middleware(e, request)
  File "C:\ProgramData\Anaconda3\lib\site-packages\django\core\handlers\base.py", line 126, in _get_response
    response = wrapped_callback(request, *callback_args, **callback_kwargs)
  File "C:\ProgramData\Anaconda3\lib\site-packages\django\views\decorators\csrf.py", line 54, in wrapped_view
    return view_func(*args, **kwargs)
  File "C:\ProgramData\Anaconda3\lib\site-packages\django\views\generic\base.py", line 69, in view
    return self.dispatch(request, *args, **kwargs)
  File "C:\ProgramData\Anaconda3\lib\site-packages\rest_framework\views.py", line 505, in dispatch
    response = self.handle_exception(exc)
  File "C:\ProgramData\Anaconda3\lib\site-packages\rest_framework\views.py", line 465, in handle_exception
    self.raise_uncaught_exception(exc)
  File "C:\ProgramData\Anaconda3\lib\site-packages\rest_framework\views.py", line 476, in raise_uncaught_exception
    raise exc
  File "C:\ProgramData\Anaconda3\lib\site-packages\rest_framework\views.py", line 502, in dispatch
    response = handler(request, *args, **kwargs)
  File "C:\Users\Administrator\PycharmProjects\riskcontrol\aaa\fin_renhang_riskcontrol\akamx\views.py", line 202, in post
    cntent = names + str(ids) + 5000
TypeError: can only concatenate str (not "int") to str
19/Feb/2020 10:55 [Thread-1: 20324]C:\ProgramData\Anaconda3\lib\site-packages\django\core\servers\basehttp.py:log_message:124 ERROR - "POST /api/ HTTP/1.1" 500 18163
