21/Feb/2020 10:46 [Thread-1: 17560]C:\Users\Administrator\PycharmProjects\riskcontrol\aaa\fin_renhang_riskcontrol\akamx\views.py:post:53 INFO - 开始时间4.3107708
21/Feb/2020 10:46 [Thread-1: 17560]C:\Users\Administrator\PycharmProjects\riskcontrol\aaa\fin_renhang_riskcontrol\akamx\views.py:post:78 INFO - requests时间4.3123299
21/Feb/2020 10:46 [Thread-1: 17560]C:\Users\Administrator\PycharmProjects\riskcontrol\aaa\fin_renhang_riskcontrol\akamx\views.py:post:82 INFO - 获取客户的时间4.3127348
21/Feb/2020 10:46 [Thread-1: 17560]C:\Users\Administrator\PycharmProjects\riskcontrol\aaa\fin_renhang_riskcontrol\akamx\views.py:post:90 INFO - 保存客户的时间4.3656573
21/Feb/2020 10:46 [Thread-1: 17560]C:\Users\Administrator\PycharmProjects\riskcontrol\aaa\fin_renhang_riskcontrol\akamx\views.py:post:97 INFO - 获取人行的数据4.3659435
21/Feb/2020 10:46 [Thread-1: 17560]C:\ProgramData\Anaconda3\lib\site-packages\django\core\handlers\exception.py:handle_uncaught_exception:118 ERROR - Internal Server Error: /api/
Traceback (most recent call last):
  File "C:\ProgramData\Anaconda3\lib\site-packages\django\core\handlers\exception.py", line 35, in inner
    response = get_response(request)
  File "C:\ProgramData\Anaconda3\lib\site-packages\django\core\handlers\base.py", line 128, in _get_response
    response = self.process_exception_by_middleware(e, request)
  File "C:\ProgramData\Anaconda3\lib\site-packages\django\core\handlers\base.py", line 126, in _get_response
    response = wrapped_callback(request, *callback_args, **callback_kwargs)
  File "C:\ProgramData\Anaconda3\lib\site-packages\django\views\decorators\csrf.py", line 54, in wrapped_view
    return view_func(*args, **kwargs)
  File "C:\ProgramData\Anaconda3\lib\site-packages\django\views\generic\base.py", line 69, in view
    return self.dispatch(request, *args, **kwargs)
  File "C:\ProgramData\Anaconda3\lib\site-packages\rest_framework\views.py", line 505, in dispatch
    response = self.handle_exception(exc)
  File "C:\ProgramData\Anaconda3\lib\site-packages\rest_framework\views.py", line 465, in handle_exception
    self.raise_uncaught_exception(exc)
  File "C:\ProgramData\Anaconda3\lib\site-packages\rest_framework\views.py", line 476, in raise_uncaught_exception
    raise exc
  File "C:\ProgramData\Anaconda3\lib\site-packages\rest_framework\views.py", line 502, in dispatch
    response = handler(request, *args, **kwargs)
  File "C:\Users\Administrator\PycharmProjects\riskcontrol\aaa\fin_renhang_riskcontrol\akamx\views.py", line 101, in post
    bl_json,xgb_score = bairong.moxing_tz()
  File "C:\Users\Administrator\PycharmProjects\riskcontrol\aaa\fin_renhang_riskcontrol\akamx\bairong.py", line 242, in moxing_tz
    results_br = Datas(self.full_name,self.id_no,self.cellphone,self.id_type).requestss()
AttributeError: 'Bairong' object has no attribute 'id_type'
21/Feb/2020 10:46 [Thread-1: 17560]C:\ProgramData\Anaconda3\lib\site-packages\django\core\servers\basehttp.py:log_message:124 ERROR - "POST /api/ HTTP/1.1" 500 16991
21/Feb/2020 10:46 [Thread-2: 14508]C:\Users\Administrator\PycharmProjects\riskcontrol\aaa\fin_renhang_riskcontrol\akamx\views.py:post:53 INFO - 开始时间8.2707856
21/Feb/2020 10:46 [Thread-2: 14508]C:\Users\Administrator\PycharmProjects\riskcontrol\aaa\fin_renhang_riskcontrol\akamx\views.py:post:78 INFO - requests时间8.2711297
21/Feb/2020 10:46 [Thread-2: 14508]C:\Users\Administrator\PycharmProjects\riskcontrol\aaa\fin_renhang_riskcontrol\akamx\views.py:post:82 INFO - 获取客户的时间8.2714495
21/Feb/2020 10:46 [Thread-2: 14508]C:\Users\Administrator\PycharmProjects\riskcontrol\aaa\fin_renhang_riskcontrol\akamx\views.py:post:90 INFO - 保存客户的时间8.327302
21/Feb/2020 10:46 [Thread-2: 14508]C:\Users\Administrator\PycharmProjects\riskcontrol\aaa\fin_renhang_riskcontrol\akamx\views.py:post:97 INFO - 获取人行的数据8.3277123
21/Feb/2020 10:46 [Thread-2: 14508]C:\ProgramData\Anaconda3\lib\site-packages\django\core\handlers\exception.py:handle_uncaught_exception:118 ERROR - Internal Server Error: /api/
Traceback (most recent call last):
  File "C:\ProgramData\Anaconda3\lib\site-packages\django\core\handlers\exception.py", line 35, in inner
    response = get_response(request)
  File "C:\ProgramData\Anaconda3\lib\site-packages\django\core\handlers\base.py", line 128, in _get_response
    response = self.process_exception_by_middleware(e, request)
  File "C:\ProgramData\Anaconda3\lib\site-packages\django\core\handlers\base.py", line 126, in _get_response
    response = wrapped_callback(request, *callback_args, **callback_kwargs)
  File "C:\ProgramData\Anaconda3\lib\site-packages\django\views\decorators\csrf.py", line 54, in wrapped_view
    return view_func(*args, **kwargs)
  File "C:\ProgramData\Anaconda3\lib\site-packages\django\views\generic\base.py", line 69, in view
    return self.dispatch(request, *args, **kwargs)
  File "C:\ProgramData\Anaconda3\lib\site-packages\rest_framework\views.py", line 505, in dispatch
    response = self.handle_exception(exc)
  File "C:\ProgramData\Anaconda3\lib\site-packages\rest_framework\views.py", line 465, in handle_exception
    self.raise_uncaught_exception(exc)
  File "C:\ProgramData\Anaconda3\lib\site-packages\rest_framework\views.py", line 476, in raise_uncaught_exception
    raise exc
  File "C:\ProgramData\Anaconda3\lib\site-packages\rest_framework\views.py", line 502, in dispatch
    response = handler(request, *args, **kwargs)
  File "C:\Users\Administrator\PycharmProjects\riskcontrol\aaa\fin_renhang_riskcontrol\akamx\views.py", line 101, in post
    bl_json,xgb_score = bairong.moxing_tz()
  File "C:\Users\Administrator\PycharmProjects\riskcontrol\aaa\fin_renhang_riskcontrol\akamx\bairong.py", line 242, in moxing_tz
    results_br = Datas(self.full_name,self.id_no,self.cellphone,self.id_type).requestss()
AttributeError: 'Bairong' object has no attribute 'id_type'
21/Feb/2020 10:46 [Thread-2: 14508]C:\ProgramData\Anaconda3\lib\site-packages\django\core\servers\basehttp.py:log_message:124 ERROR - "POST /api/ HTTP/1.1" 500 16991
