20/Feb/2020 13:00 [Thread-1: 17592]C:\Users\Administrator\PycharmProjects\riskcontrol\aaa\fin_renhang_riskcontrol\akamx\views.py:post:53 INFO - 开始时间9.0519268
20/Feb/2020 13:00 [Thread-1: 17592]C:\Users\Administrator\PycharmProjects\riskcontrol\aaa\fin_renhang_riskcontrol\akamx\views.py:post:78 INFO - requests时间9.0530561
20/Feb/2020 13:00 [Thread-1: 17592]C:\Users\Administrator\PycharmProjects\riskcontrol\aaa\fin_renhang_riskcontrol\akamx\views.py:post:82 INFO - 获取客户的时间9.0533911
20/Feb/2020 13:00 [Thread-1: 17592]C:\Users\Administrator\PycharmProjects\riskcontrol\aaa\fin_renhang_riskcontrol\akamx\views.py:post:90 INFO - 保存客户的时间9.0993306
20/Feb/2020 13:00 [Thread-1: 17592]C:\Users\Administrator\PycharmProjects\riskcontrol\aaa\fin_renhang_riskcontrol\akamx\views.py:post:97 INFO - 获取人行的数据9.0996712
20/Feb/2020 13:00 [Thread-1: 17592]C:\ProgramData\Anaconda3\lib\site-packages\django\core\handlers\exception.py:handle_uncaught_exception:118 ERROR - Internal Server Error: /api/
Traceback (most recent call last):
  File "C:\ProgramData\Anaconda3\lib\site-packages\django\core\handlers\exception.py", line 35, in inner
    response = get_response(request)
  File "C:\ProgramData\Anaconda3\lib\site-packages\django\core\handlers\base.py", line 128, in _get_response
    response = self.process_exception_by_middleware(e, request)
  File "C:\ProgramData\Anaconda3\lib\site-packages\django\core\handlers\base.py", line 126, in _get_response
    response = wrapped_callback(request, *callback_args, **callback_kwargs)
  File "C:\ProgramData\Anaconda3\lib\site-packages\django\views\decorators\csrf.py", line 54, in wrapped_view
    return view_func(*args, **kwargs)
  File "C:\ProgramData\Anaconda3\lib\site-packages\django\views\generic\base.py", line 69, in view
    return self.dispatch(request, *args, **kwargs)
  File "C:\ProgramData\Anaconda3\lib\site-packages\rest_framework\views.py", line 505, in dispatch
    response = self.handle_exception(exc)
  File "C:\ProgramData\Anaconda3\lib\site-packages\rest_framework\views.py", line 465, in handle_exception
    self.raise_uncaught_exception(exc)
  File "C:\ProgramData\Anaconda3\lib\site-packages\rest_framework\views.py", line 476, in raise_uncaught_exception
    raise exc
  File "C:\ProgramData\Anaconda3\lib\site-packages\rest_framework\views.py", line 502, in dispatch
    response = handler(request, *args, **kwargs)
  File "C:\Users\Administrator\PycharmProjects\riskcontrol\aaa\fin_renhang_riskcontrol\akamx\views.py", line 101, in post
    bl_json = bairong.moxing_tz()
  File "C:\Users\Administrator\PycharmProjects\riskcontrol\aaa\fin_renhang_riskcontrol\akamx\bairong.py", line 284, in moxing_tz
    p = xgb.predict_proba(df_all[feature])[:, 1]
  File "C:\ProgramData\Anaconda3\lib\site-packages\xgboost\sklearn.py", line 829, in predict_proba
    test_dmatrix = DMatrix(data, missing=self.missing, nthread=self.n_jobs)
  File "C:\ProgramData\Anaconda3\lib\site-packages\xgboost\core.py", line 380, in __init__
    feature_types)
  File "C:\ProgramData\Anaconda3\lib\site-packages\xgboost\core.py", line 239, in _maybe_pandas_data
    raise ValueError(msg + ', '.join(bad_fields))
ValueError: DataFrame.dtypes for data must be int, float or bool.
                Did not expect the data types in fields als_m12_cell_nbank_else_orgnum, als_m12_id_nbank_orgnum, als_lst_cell_nbank_csinteday, als_m6_cell_nbank_ca_allnum, als_m3_cell_rel_allnum, als_m6_cell_nbank_cf_allnum, als_m6_id_nbank_sloan_allnum, als_m3_id_nbank_ca_allnum, als_lst_id_nbank_csinteday, als_m3_id_nbank_cons_allnum, als_m6_cell_nbank_sloan_allnum, als_m12_cell_nbank_ca_orgnum, als_m6_cell_nbank_cons_allnum, als_m3_id_nbank_min_monnum, als_m12_cell_bank_night_allnum, als_m6_cell_bank_orgnum, als_m12_id_oth_orgnum, als_m12_id_nbank_tot_mons, als_m3_id_nbank_max_monnum, als_m6_id_max_monnum, als_m12_id_pdl_orgnum, als_m12_cell_bank_week_allnum, als_m12_cell_bank_avg_monnum, als_m1_cell_nbank_allnum, als_m3_cell_bank_week_allnum, als_m1_id_nbank_night_allnum, ir_m3_id_x_mail_cnt, ir_m12_id_x_biz_work_cnt, ir_m3_id_x_cell_cnt, ir_m1_id_x_home_addr_cnt, ir_m6_cell_x_linkman_cell_cnt, ir_m1_cell_x_device_cnt, ir_m3_cell_x_biz_addr_cnt, ir_m1_cell_x_linkman_cell_cnt, ir_m1_id_x_device_cnt, ir_m6_id_x_tel_biz_cnt, ir_cell_inlistwith_id, ir_m1_id_x_linkman_cell_cnt, ir_m6_id_x_cell_cnt, ir_m6_id_x_linkman_cell_cnt, ir_m3_id_x_home_addr_cnt, ir_m6_cell_x_id_cnt, ir_m6_cell_x_biz_addr_cnt, ir_m12_id_x_home_addr_cnt, ir_m12_id_x_device_cnt, ir_m3_cell_x_biz_work_cnt, ir_m12_id_x_linkman_cell_cnt, ir_m6_id_x_tel_home_cnt, ir_m3_cell_x_name_cnt, ir_m1_cell_x_name_cnt, ir_m6_id_x_biz_addr_cnt, ir_id_x_cell_notmat_days, ir_m12_cell_x_id_cnt, ir_m6_cell_x_name_cnt, ir_m6_id_x_home_addr_cnt, ir_m1_id_x_tel_home_cnt, ir_m1_cell_x_id_cnt, ir_cell_is_reabnormal, ir_id_is_reabnormal, ir_m6_id_x_biz_work_cnt, ir_m3_cell_x_mail_cnt, ir_m6_cell_x_device_cnt, ir_m1_id_x_tel_biz_cnt, ir_m12_cell_x_home_addr_cnt, ir_m1_cell_x_tel_biz_cnt, ir_m12_cell_x_device_cnt, ir_m1_cell_x_tel_home_cnt, ir_m12_cell_x_biz_addr_cnt, ir_m12_cell_x_linkman_cell_cnt, ir_m12_id_x_tel_home_cnt, ir_m3_id_x_biz_work_cnt, ir_m12_cell_x_tel_home_cnt, ir_id_x_cell_cnt, ir_m1_id_x_mail_cnt, ir_m3_cell_x_tel_biz_cnt, ir_m3_id_x_device_cnt, ir_m1_cell_x_biz_addr_cnt, ir_m6_id_x_device_cnt, ir_m3_cell_x_linkman_cell_cnt, ir_m3_id_x_linkman_cell_cnt, ir_m1_id_x_cell_cnt, ir_allmatch_days, ir_m6_cell_x_home_addr_cnt, ir_m1_cell_x_home_addr_cnt, ir_m1_id_x_biz_work_cnt, ir_m3_cell_x_id_cnt, flag_fraudrelation_g, flag_applyloanstr, flag_inforelation, frg_list_level, frg_group_num, id_city
20/Feb/2020 13:00 [Thread-1: 17592]C:\ProgramData\Anaconda3\lib\site-packages\django\core\servers\basehttp.py:log_message:124 ERROR - "POST /api/ HTTP/1.1" 500 22223
