21/Feb/2020 16:30 [Thread-5: 6624]C:\ProgramData\Anaconda3\lib\site-packages\django\core\handlers\base.py:get_response:93 WARNING - Not Found: /all/
21/Feb/2020 16:30 [Thread-5: 6624]C:\ProgramData\Anaconda3\lib\site-packages\django\core\servers\basehttp.py:log_message:124 WARNING - "POST /all/ HTTP/1.1" 404 2285
21/Feb/2020 16:30 [Thread-1: 21912]C:\ProgramData\Anaconda3\lib\site-packages\django\core\handlers\exception.py:handle_uncaught_exception:118 ERROR - Internal Server Error: /all/
Traceback (most recent call last):
  File "C:\ProgramData\Anaconda3\lib\site-packages\django\core\handlers\exception.py", line 35, in inner
    response = get_response(request)
  File "C:\ProgramData\Anaconda3\lib\site-packages\django\core\handlers\base.py", line 128, in _get_response
    response = self.process_exception_by_middleware(e, request)
  File "C:\ProgramData\Anaconda3\lib\site-packages\django\core\handlers\base.py", line 126, in _get_response
    response = wrapped_callback(request, *callback_args, **callback_kwargs)
TypeError: __init__() takes 1 positional argument but 2 were given
21/Feb/2020 16:30 [Thread-1: 21912]C:\ProgramData\Anaconda3\lib\site-packages\django\core\servers\basehttp.py:log_message:124 ERROR - "POST /all/ HTTP/1.1" 500 62805
