10/Feb/2020 13:46 [Thread-2: 492]C:\Users\Administrator\PycharmProjects\riskcontrol\aaa\fin_renhang_riskcontrol\ghrule\views.py:post:25 INFO - 开始时间53.6187177
10/Feb/2020 13:46 [Thread-2: 492]C:\Users\Administrator\PycharmProjects\riskcontrol\aaa\fin_renhang_riskcontrol\ghrule\views.py:post:31 INFO - {'full_name': '庞明', 'id_type': '0', 'id_no': '511304199906271151'}
10/Feb/2020 13:46 [Thread-2: 492]C:\Users\Administrator\PycharmProjects\riskcontrol\aaa\fin_renhang_riskcontrol\ghrule\views.py:post:55 INFO - 开始调用时间53.620706
10/Feb/2020 13:46 [Thread-2: 492]C:\Users\Administrator\PycharmProjects\riskcontrol\aaa\fin_renhang_riskcontrol\ghrule\renhang.py:renhanhgomngshang:309 INFO - 调取人行接口开始时间53.6209307
10/Feb/2020 13:46 [Thread-2: 492]C:\Users\Administrator\PycharmProjects\riskcontrol\aaa\fin_renhang_riskcontrol\ghrule\renhang.py:renhanhgomngshang:313 INFO - 调取人行接口结束时间53.8253893
10/Feb/2020 13:46 [Thread-2: 492]C:\Users\Administrator\PycharmProjects\riskcontrol\aaa\fin_renhang_riskcontrol\ghrule\renhang.py:renhanhgomngshang:315 INFO - 调取人行接口总共所用时间0.20445859999999527
10/Feb/2020 13:46 [Thread-2: 492]C:\Users\Administrator\PycharmProjects\riskcontrol\aaa\fin_renhang_riskcontrol\ghrule\renhang.py:renhanhgomngshang:375 INFO - 错误的信息4000
10/Feb/2020 13:46 [Thread-2: 492]C:\Users\Administrator\PycharmProjects\riskcontrol\aaa\fin_renhang_riskcontrol\ghrule\renhang.py:renhanhgomngshang:379 INFO - 调取函数结束时间53.9027497
10/Feb/2020 13:46 [Thread-2: 492]C:\Users\Administrator\PycharmProjects\riskcontrol\aaa\fin_renhang_riskcontrol\ghrule\renhang.py:renhanhgomngshang:381 INFO - 总共所用时间0.2818189999999987
10/Feb/2020 13:46 [Thread-2: 492]C:\Users\Administrator\PycharmProjects\riskcontrol\aaa\fin_renhang_riskcontrol\ghrule\renhang.py:renhanhgomngshang:383 INFO - 调取人行数据和总函数时间的比例0.7254961517853523
10/Feb/2020 13:46 [Thread-2: 492]C:\Users\Administrator\PycharmProjects\riskcontrol\aaa\fin_renhang_riskcontrol\ghrule\views.py:post:60 INFO - 调用结束的时间53.9034241
10/Feb/2020 13:46 [Thread-2: 492]C:\Users\Administrator\PycharmProjects\riskcontrol\aaa\fin_renhang_riskcontrol\ghrule\views.py:post:61 INFO - 调用总共的时间0.28271810000000386
10/Feb/2020 13:46 [Thread-2: 492]C:\Users\Administrator\PycharmProjects\riskcontrol\aaa\fin_renhang_riskcontrol\ghrule\views.py:post:62 INFO - 4000
10/Feb/2020 13:46 [Thread-2: 492]C:\Users\Administrator\PycharmProjects\riskcontrol\aaa\fin_renhang_riskcontrol\ghrule\views.py:post:97 INFO - 错误的信息
10/Feb/2020 13:46 [Thread-2: 492]C:\Users\Administrator\PycharmProjects\riskcontrol\aaa\fin_renhang_riskcontrol\ghrule\views.py:post:99 INFO - 错误时候返回来所用时间0.2855380000000025
10/Feb/2020 13:46 [Thread-2: 492]C:\ProgramData\Anaconda3\lib\site-packages\django\core\handlers\exception.py:handle_uncaught_exception:118 ERROR - Internal Server Error: /gonghang/
Traceback (most recent call last):
  File "C:\Users\Administrator\PycharmProjects\riskcontrol\aaa\fin_renhang_riskcontrol\ghrule\views.py", line 69, in post
    mail.send_mail()
  File "C:\Users\Administrator\PycharmProjects\riskcontrol\aaa\fin_renhang_riskcontrol\Emailsend\send.py", line 54, in send_mail
    msg.attach(MIMEText(self.content))#邮件正文的内容
  File "C:\ProgramData\Anaconda3\lib\email\mime\text.py", line 34, in __init__
    _text.encode('us-ascii')
AttributeError: 'dict' object has no attribute 'encode'

During handling of the above exception, another exception occurred:

Traceback (most recent call last):
  File "C:\ProgramData\Anaconda3\lib\site-packages\django\core\handlers\exception.py", line 35, in inner
    response = get_response(request)
  File "C:\ProgramData\Anaconda3\lib\site-packages\django\core\handlers\base.py", line 128, in _get_response
    response = self.process_exception_by_middleware(e, request)
  File "C:\ProgramData\Anaconda3\lib\site-packages\django\core\handlers\base.py", line 126, in _get_response
    response = wrapped_callback(request, *callback_args, **callback_kwargs)
  File "C:\ProgramData\Anaconda3\lib\site-packages\django\views\decorators\csrf.py", line 54, in wrapped_view
    return view_func(*args, **kwargs)
  File "C:\ProgramData\Anaconda3\lib\site-packages\django\views\generic\base.py", line 69, in view
    return self.dispatch(request, *args, **kwargs)
  File "C:\ProgramData\Anaconda3\lib\site-packages\rest_framework\views.py", line 505, in dispatch
    response = self.handle_exception(exc)
  File "C:\ProgramData\Anaconda3\lib\site-packages\rest_framework\views.py", line 465, in handle_exception
    self.raise_uncaught_exception(exc)
  File "C:\ProgramData\Anaconda3\lib\site-packages\rest_framework\views.py", line 476, in raise_uncaught_exception
    raise exc
  File "C:\ProgramData\Anaconda3\lib\site-packages\rest_framework\views.py", line 502, in dispatch
    response = handler(request, *args, **kwargs)
  File "C:\Users\Administrator\PycharmProjects\riskcontrol\aaa\fin_renhang_riskcontrol\ghrule\views.py", line 100, in post
    mail.send_mail()
  File "C:\Users\Administrator\PycharmProjects\riskcontrol\aaa\fin_renhang_riskcontrol\Emailsend\send.py", line 54, in send_mail
    msg.attach(MIMEText(self.content))#邮件正文的内容
  File "C:\ProgramData\Anaconda3\lib\email\mime\text.py", line 34, in __init__
    _text.encode('us-ascii')
AttributeError: 'dict' object has no attribute 'encode'
10/Feb/2020 13:46 [Thread-2: 492]C:\ProgramData\Anaconda3\lib\site-packages\django\core\servers\basehttp.py:log_message:124 ERROR - "POST /gonghang/ HTTP/1.1" 500 17468
10/Feb/2020 13:46 [Thread-3: 10100]C:\Users\Administrator\PycharmProjects\riskcontrol\aaa\fin_renhang_riskcontrol\ghrule\views.py:post:25 INFO - 开始时间54.6838644
10/Feb/2020 13:46 [Thread-3: 10100]C:\Users\Administrator\PycharmProjects\riskcontrol\aaa\fin_renhang_riskcontrol\ghrule\views.py:post:31 INFO - {'full_name': '庞明', 'id_type': '0', 'id_no': '511304199906271151'}
10/Feb/2020 13:46 [Thread-3: 10100]C:\Users\Administrator\PycharmProjects\riskcontrol\aaa\fin_renhang_riskcontrol\ghrule\views.py:post:55 INFO - 开始调用时间54.6846099
10/Feb/2020 13:46 [Thread-3: 10100]C:\Users\Administrator\PycharmProjects\riskcontrol\aaa\fin_renhang_riskcontrol\ghrule\renhang.py:renhanhgomngshang:309 INFO - 调取人行接口开始时间54.6848017
10/Feb/2020 13:46 [Thread-3: 10100]C:\Users\Administrator\PycharmProjects\riskcontrol\aaa\fin_renhang_riskcontrol\ghrule\renhang.py:renhanhgomngshang:313 INFO - 调取人行接口结束时间54.8715391
10/Feb/2020 13:46 [Thread-3: 10100]C:\Users\Administrator\PycharmProjects\riskcontrol\aaa\fin_renhang_riskcontrol\ghrule\renhang.py:renhanhgomngshang:315 INFO - 调取人行接口总共所用时间0.1867373999999984
10/Feb/2020 13:46 [Thread-3: 10100]C:\Users\Administrator\PycharmProjects\riskcontrol\aaa\fin_renhang_riskcontrol\ghrule\renhang.py:renhanhgomngshang:375 INFO - 错误的信息4000
10/Feb/2020 13:46 [Thread-3: 10100]C:\Users\Administrator\PycharmProjects\riskcontrol\aaa\fin_renhang_riskcontrol\ghrule\renhang.py:renhanhgomngshang:379 INFO - 调取函数结束时间54.9529847
10/Feb/2020 13:46 [Thread-3: 10100]C:\Users\Administrator\PycharmProjects\riskcontrol\aaa\fin_renhang_riskcontrol\ghrule\renhang.py:renhanhgomngshang:381 INFO - 总共所用时间0.2681830000000005
10/Feb/2020 13:46 [Thread-3: 10100]C:\Users\Administrator\PycharmProjects\riskcontrol\aaa\fin_renhang_riskcontrol\ghrule\renhang.py:renhanhgomngshang:383 INFO - 调取人行数据和总函数时间的比例0.6963058806859422
10/Feb/2020 13:46 [Thread-3: 10100]C:\Users\Administrator\PycharmProjects\riskcontrol\aaa\fin_renhang_riskcontrol\ghrule\views.py:post:60 INFO - 调用结束的时间54.9536564
10/Feb/2020 13:46 [Thread-3: 10100]C:\Users\Administrator\PycharmProjects\riskcontrol\aaa\fin_renhang_riskcontrol\ghrule\views.py:post:61 INFO - 调用总共的时间0.26904650000000174
10/Feb/2020 13:46 [Thread-3: 10100]C:\Users\Administrator\PycharmProjects\riskcontrol\aaa\fin_renhang_riskcontrol\ghrule\views.py:post:62 INFO - 4000
10/Feb/2020 13:46 [Thread-3: 10100]C:\Users\Administrator\PycharmProjects\riskcontrol\aaa\fin_renhang_riskcontrol\ghrule\views.py:post:97 INFO - 错误的信息
10/Feb/2020 13:46 [Thread-3: 10100]C:\Users\Administrator\PycharmProjects\riskcontrol\aaa\fin_renhang_riskcontrol\ghrule\views.py:post:99 INFO - 错误时候返回来所用时间0.27075170000000526
10/Feb/2020 13:46 [Thread-3: 10100]C:\ProgramData\Anaconda3\lib\site-packages\django\core\handlers\exception.py:handle_uncaught_exception:118 ERROR - Internal Server Error: /gonghang/
Traceback (most recent call last):
  File "C:\Users\Administrator\PycharmProjects\riskcontrol\aaa\fin_renhang_riskcontrol\ghrule\views.py", line 69, in post
    mail.send_mail()
  File "C:\Users\Administrator\PycharmProjects\riskcontrol\aaa\fin_renhang_riskcontrol\Emailsend\send.py", line 54, in send_mail
    msg.attach(MIMEText(self.content))#邮件正文的内容
  File "C:\ProgramData\Anaconda3\lib\email\mime\text.py", line 34, in __init__
    _text.encode('us-ascii')
AttributeError: 'dict' object has no attribute 'encode'

During handling of the above exception, another exception occurred:

Traceback (most recent call last):
  File "C:\ProgramData\Anaconda3\lib\site-packages\django\core\handlers\exception.py", line 35, in inner
    response = get_response(request)
  File "C:\ProgramData\Anaconda3\lib\site-packages\django\core\handlers\base.py", line 128, in _get_response
    response = self.process_exception_by_middleware(e, request)
  File "C:\ProgramData\Anaconda3\lib\site-packages\django\core\handlers\base.py", line 126, in _get_response
    response = wrapped_callback(request, *callback_args, **callback_kwargs)
  File "C:\ProgramData\Anaconda3\lib\site-packages\django\views\decorators\csrf.py", line 54, in wrapped_view
    return view_func(*args, **kwargs)
  File "C:\ProgramData\Anaconda3\lib\site-packages\django\views\generic\base.py", line 69, in view
    return self.dispatch(request, *args, **kwargs)
  File "C:\ProgramData\Anaconda3\lib\site-packages\rest_framework\views.py", line 505, in dispatch
    response = self.handle_exception(exc)
  File "C:\ProgramData\Anaconda3\lib\site-packages\rest_framework\views.py", line 465, in handle_exception
    self.raise_uncaught_exception(exc)
  File "C:\ProgramData\Anaconda3\lib\site-packages\rest_framework\views.py", line 476, in raise_uncaught_exception
    raise exc
  File "C:\ProgramData\Anaconda3\lib\site-packages\rest_framework\views.py", line 502, in dispatch
    response = handler(request, *args, **kwargs)
  File "C:\Users\Administrator\PycharmProjects\riskcontrol\aaa\fin_renhang_riskcontrol\ghrule\views.py", line 100, in post
    mail.send_mail()
  File "C:\Users\Administrator\PycharmProjects\riskcontrol\aaa\fin_renhang_riskcontrol\Emailsend\send.py", line 54, in send_mail
    msg.attach(MIMEText(self.content))#邮件正文的内容
  File "C:\ProgramData\Anaconda3\lib\email\mime\text.py", line 34, in __init__
    _text.encode('us-ascii')
AttributeError: 'dict' object has no attribute 'encode'
10/Feb/2020 13:46 [Thread-3: 10100]C:\ProgramData\Anaconda3\lib\site-packages\django\core\servers\basehttp.py:log_message:124 ERROR - "POST /gonghang/ HTTP/1.1" 500 17468
10/Feb/2020 13:46 [Thread-1: 9420]C:\Users\Administrator\PycharmProjects\riskcontrol\aaa\fin_renhang_riskcontrol\ghrule\views.py:post:25 INFO - 开始时间5.1334094
10/Feb/2020 13:46 [Thread-1: 9420]C:\Users\Administrator\PycharmProjects\riskcontrol\aaa\fin_renhang_riskcontrol\ghrule\views.py:post:31 INFO - {'full_name': '庞明', 'id_type': '0', 'id_no': '511304199906271151'}
10/Feb/2020 13:46 [Thread-1: 9420]C:\Users\Administrator\PycharmProjects\riskcontrol\aaa\fin_renhang_riskcontrol\ghrule\views.py:post:55 INFO - 开始调用时间5.1564212
10/Feb/2020 13:46 [Thread-1: 9420]C:\Users\Administrator\PycharmProjects\riskcontrol\aaa\fin_renhang_riskcontrol\ghrule\renhang.py:renhanhgomngshang:309 INFO - 调取人行接口开始时间5.1566494
10/Feb/2020 13:46 [Thread-1: 9420]C:\Users\Administrator\PycharmProjects\riskcontrol\aaa\fin_renhang_riskcontrol\ghrule\renhang.py:renhanhgomngshang:313 INFO - 调取人行接口结束时间5.343442
10/Feb/2020 13:46 [Thread-1: 9420]C:\Users\Administrator\PycharmProjects\riskcontrol\aaa\fin_renhang_riskcontrol\ghrule\renhang.py:renhanhgomngshang:315 INFO - 调取人行接口总共所用时间0.18679259999999953
10/Feb/2020 13:46 [Thread-1: 9420]C:\Users\Administrator\PycharmProjects\riskcontrol\aaa\fin_renhang_riskcontrol\ghrule\renhang.py:renhanhgomngshang:375 INFO - 错误的信息4000
10/Feb/2020 13:46 [Thread-1: 9420]C:\Users\Administrator\PycharmProjects\riskcontrol\aaa\fin_renhang_riskcontrol\ghrule\renhang.py:renhanhgomngshang:379 INFO - 调取函数结束时间5.4079101
10/Feb/2020 13:46 [Thread-1: 9420]C:\Users\Administrator\PycharmProjects\riskcontrol\aaa\fin_renhang_riskcontrol\ghrule\renhang.py:renhanhgomngshang:381 INFO - 总共所用时间0.25126069999999956
10/Feb/2020 13:46 [Thread-1: 9420]C:\Users\Administrator\PycharmProjects\riskcontrol\aaa\fin_renhang_riskcontrol\ghrule\renhang.py:renhanhgomngshang:383 INFO - 调取人行数据和总函数时间的比例0.7434214741899543
10/Feb/2020 13:46 [Thread-1: 9420]C:\Users\Administrator\PycharmProjects\riskcontrol\aaa\fin_renhang_riskcontrol\ghrule\views.py:post:60 INFO - 调用结束的时间5.4087098
10/Feb/2020 13:46 [Thread-1: 9420]C:\Users\Administrator\PycharmProjects\riskcontrol\aaa\fin_renhang_riskcontrol\ghrule\views.py:post:61 INFO - 调用总共的时间0.2522886
10/Feb/2020 13:46 [Thread-1: 9420]C:\Users\Administrator\PycharmProjects\riskcontrol\aaa\fin_renhang_riskcontrol\ghrule\views.py:post:62 INFO - 4000
10/Feb/2020 13:46 [Thread-1: 9420]C:\Users\Administrator\PycharmProjects\riskcontrol\aaa\fin_renhang_riskcontrol\ghrule\views.py:post:97 INFO - 错误的信息
10/Feb/2020 13:46 [Thread-1: 9420]C:\Users\Administrator\PycharmProjects\riskcontrol\aaa\fin_renhang_riskcontrol\ghrule\views.py:post:99 INFO - 错误时候返回来所用时间0.2762372000000006
10/Feb/2020 13:46 [Thread-1: 9420]C:\ProgramData\Anaconda3\lib\site-packages\django\core\handlers\exception.py:handle_uncaught_exception:118 ERROR - Internal Server Error: /gonghang/
Traceback (most recent call last):
  File "C:\Users\Administrator\PycharmProjects\riskcontrol\aaa\fin_renhang_riskcontrol\ghrule\views.py", line 69, in post
    mail.send_mail()
  File "C:\Users\Administrator\PycharmProjects\riskcontrol\aaa\fin_renhang_riskcontrol\Emailsend\send.py", line 54, in send_mail
    msg.attach(MIMEText(self.content))#邮件正文的内容
  File "C:\ProgramData\Anaconda3\lib\email\mime\text.py", line 34, in __init__
    _text.encode('us-ascii')
AttributeError: 'list' object has no attribute 'encode'

During handling of the above exception, another exception occurred:

Traceback (most recent call last):
  File "C:\ProgramData\Anaconda3\lib\site-packages\django\core\handlers\exception.py", line 35, in inner
    response = get_response(request)
  File "C:\ProgramData\Anaconda3\lib\site-packages\django\core\handlers\base.py", line 128, in _get_response
    response = self.process_exception_by_middleware(e, request)
  File "C:\ProgramData\Anaconda3\lib\site-packages\django\core\handlers\base.py", line 126, in _get_response
    response = wrapped_callback(request, *callback_args, **callback_kwargs)
  File "C:\ProgramData\Anaconda3\lib\site-packages\django\views\decorators\csrf.py", line 54, in wrapped_view
    return view_func(*args, **kwargs)
  File "C:\ProgramData\Anaconda3\lib\site-packages\django\views\generic\base.py", line 69, in view
    return self.dispatch(request, *args, **kwargs)
  File "C:\ProgramData\Anaconda3\lib\site-packages\rest_framework\views.py", line 505, in dispatch
    response = self.handle_exception(exc)
  File "C:\ProgramData\Anaconda3\lib\site-packages\rest_framework\views.py", line 465, in handle_exception
    self.raise_uncaught_exception(exc)
  File "C:\ProgramData\Anaconda3\lib\site-packages\rest_framework\views.py", line 476, in raise_uncaught_exception
    raise exc
  File "C:\ProgramData\Anaconda3\lib\site-packages\rest_framework\views.py", line 502, in dispatch
    response = handler(request, *args, **kwargs)
  File "C:\Users\Administrator\PycharmProjects\riskcontrol\aaa\fin_renhang_riskcontrol\ghrule\views.py", line 100, in post
    mail.send_mail()
  File "C:\Users\Administrator\PycharmProjects\riskcontrol\aaa\fin_renhang_riskcontrol\Emailsend\send.py", line 54, in send_mail
    msg.attach(MIMEText(self.content))#邮件正文的内容
  File "C:\ProgramData\Anaconda3\lib\email\mime\text.py", line 34, in __init__
    _text.encode('us-ascii')
AttributeError: 'list' object has no attribute 'encode'
10/Feb/2020 13:46 [Thread-1: 9420]C:\ProgramData\Anaconda3\lib\site-packages\django\core\servers\basehttp.py:log_message:124 ERROR - "POST /gonghang/ HTTP/1.1" 500 17468
