20/Feb/2020 18:30 [Thread-1: 13308]C:\Users\Administrator\PycharmProjects\riskcontrol\aaa\fin_renhang_riskcontrol\akamx\views.py:post:53 INFO - 开始时间4.2904876
20/Feb/2020 18:30 [Thread-1: 13308]C:\Users\Administrator\PycharmProjects\riskcontrol\aaa\fin_renhang_riskcontrol\akamx\views.py:post:78 INFO - requests时间4.2921002
20/Feb/2020 18:30 [Thread-1: 13308]C:\Users\Administrator\PycharmProjects\riskcontrol\aaa\fin_renhang_riskcontrol\akamx\views.py:post:82 INFO - 获取客户的时间4.2925653
20/Feb/2020 18:30 [Thread-1: 13308]C:\Users\Administrator\PycharmProjects\riskcontrol\aaa\fin_renhang_riskcontrol\akamx\views.py:post:90 INFO - 保存客户的时间4.3476387
20/Feb/2020 18:30 [Thread-1: 13308]C:\Users\Administrator\PycharmProjects\riskcontrol\aaa\fin_renhang_riskcontrol\akamx\views.py:post:97 INFO - 获取人行的数据4.3479852
20/Feb/2020 18:30 [Thread-1: 13308]C:\Users\Administrator\PycharmProjects\riskcontrol\aaa\fin_renhang_riskcontrol\akamx\views.py:post:104 INFO - 获取三方数据5.754914
20/Feb/2020 18:30 [Thread-1: 13308]C:\Users\Administrator\PycharmProjects\riskcontrol\aaa\fin_renhang_riskcontrol\akamx\views.py:post:164 INFO - 输出最终数据6.8842264
20/Feb/2020 18:30 [Thread-1: 13308]C:\Users\Administrator\PycharmProjects\riskcontrol\aaa\fin_renhang_riskcontrol\akamx\views.py:post:174 INFO - 保存数据6.9042512
20/Feb/2020 18:30 [Thread-1: 13308]C:\Users\Administrator\PycharmProjects\riskcontrol\aaa\fin_renhang_riskcontrol\akamx\views.py:post:190 INFO - 结束时间6.9045684
20/Feb/2020 18:30 [Thread-1: 13308]C:\Users\Administrator\PycharmProjects\riskcontrol\aaa\fin_renhang_riskcontrol\akamx\views.py:post:192 INFO - 总共用时间是2.6140808
20/Feb/2020 18:30 [Thread-1: 13308]C:\ProgramData\Anaconda3\lib\site-packages\django\core\servers\basehttp.py:log_message:124 INFO - "POST /api/ HTTP/1.1" 200 15
20/Feb/2020 18:30 [Thread-2: 15504]C:\Users\Administrator\PycharmProjects\riskcontrol\aaa\fin_renhang_riskcontrol\akamx\views.py:post:53 INFO - 开始时间7.9670541
20/Feb/2020 18:30 [Thread-2: 15504]C:\Users\Administrator\PycharmProjects\riskcontrol\aaa\fin_renhang_riskcontrol\akamx\views.py:post:78 INFO - requests时间7.9673759
20/Feb/2020 18:30 [Thread-2: 15504]C:\Users\Administrator\PycharmProjects\riskcontrol\aaa\fin_renhang_riskcontrol\akamx\views.py:post:82 INFO - 获取客户的时间7.9677592
20/Feb/2020 18:30 [Thread-2: 15504]C:\Users\Administrator\PycharmProjects\riskcontrol\aaa\fin_renhang_riskcontrol\akamx\views.py:post:90 INFO - 保存客户的时间8.0232074
20/Feb/2020 18:30 [Thread-2: 15504]C:\Users\Administrator\PycharmProjects\riskcontrol\aaa\fin_renhang_riskcontrol\akamx\views.py:post:97 INFO - 获取人行的数据8.0235722
20/Feb/2020 18:30 [Thread-2: 15504]C:\ProgramData\Anaconda3\lib\site-packages\django\core\handlers\exception.py:handle_uncaught_exception:118 ERROR - Internal Server Error: /api/
Traceback (most recent call last):
  File "C:\ProgramData\Anaconda3\lib\site-packages\django\core\handlers\exception.py", line 35, in inner
    response = get_response(request)
  File "C:\ProgramData\Anaconda3\lib\site-packages\django\core\handlers\base.py", line 128, in _get_response
    response = self.process_exception_by_middleware(e, request)
  File "C:\ProgramData\Anaconda3\lib\site-packages\django\core\handlers\base.py", line 126, in _get_response
    response = wrapped_callback(request, *callback_args, **callback_kwargs)
  File "C:\ProgramData\Anaconda3\lib\site-packages\django\views\decorators\csrf.py", line 54, in wrapped_view
    return view_func(*args, **kwargs)
  File "C:\ProgramData\Anaconda3\lib\site-packages\django\views\generic\base.py", line 69, in view
    return self.dispatch(request, *args, **kwargs)
  File "C:\ProgramData\Anaconda3\lib\site-packages\rest_framework\views.py", line 505, in dispatch
    response = self.handle_exception(exc)
  File "C:\ProgramData\Anaconda3\lib\site-packages\rest_framework\views.py", line 465, in handle_exception
    self.raise_uncaught_exception(exc)
  File "C:\ProgramData\Anaconda3\lib\site-packages\rest_framework\views.py", line 476, in raise_uncaught_exception
    raise exc
  File "C:\ProgramData\Anaconda3\lib\site-packages\rest_framework\views.py", line 502, in dispatch
    response = handler(request, *args, **kwargs)
  File "C:\Users\Administrator\PycharmProjects\riskcontrol\aaa\fin_renhang_riskcontrol\akamx\views.py", line 101, in post
    bl_json,xgb_score = bairong.moxing_tz()
  File "C:\Users\Administrator\PycharmProjects\riskcontrol\aaa\fin_renhang_riskcontrol\akamx\bairong.py", line 252, in moxing_tz
    bl_json,xgb_score = self.bar_moing(results_br)
  File "C:\Users\Administrator\PycharmProjects\riskcontrol\aaa\fin_renhang_riskcontrol\akamx\bairong.py", line 124, in bar_moing
    www = lujins.shenfen()
TypeError: 'DataFrame' object is not callable
20/Feb/2020 18:30 [Thread-2: 15504]C:\ProgramData\Anaconda3\lib\site-packages\django\core\servers\basehttp.py:log_message:124 ERROR - "POST /api/ HTTP/1.1" 500 17079
20/Feb/2020 18:30 [Thread-3: 9856]C:\Users\Administrator\PycharmProjects\riskcontrol\aaa\fin_renhang_riskcontrol\akamx\views.py:post:53 INFO - 开始时间10.5314934
20/Feb/2020 18:30 [Thread-3: 9856]C:\Users\Administrator\PycharmProjects\riskcontrol\aaa\fin_renhang_riskcontrol\akamx\views.py:post:78 INFO - requests时间10.5318661
20/Feb/2020 18:30 [Thread-3: 9856]C:\Users\Administrator\PycharmProjects\riskcontrol\aaa\fin_renhang_riskcontrol\akamx\views.py:post:82 INFO - 获取客户的时间10.532207
20/Feb/2020 18:30 [Thread-3: 9856]C:\Users\Administrator\PycharmProjects\riskcontrol\aaa\fin_renhang_riskcontrol\akamx\views.py:post:90 INFO - 保存客户的时间10.5876844
20/Feb/2020 18:30 [Thread-3: 9856]C:\Users\Administrator\PycharmProjects\riskcontrol\aaa\fin_renhang_riskcontrol\akamx\views.py:post:97 INFO - 获取人行的数据10.5879909
20/Feb/2020 18:30 [Thread-3: 9856]C:\ProgramData\Anaconda3\lib\site-packages\django\core\handlers\exception.py:handle_uncaught_exception:118 ERROR - Internal Server Error: /api/
Traceback (most recent call last):
  File "C:\ProgramData\Anaconda3\lib\site-packages\django\core\handlers\exception.py", line 35, in inner
    response = get_response(request)
  File "C:\ProgramData\Anaconda3\lib\site-packages\django\core\handlers\base.py", line 128, in _get_response
    response = self.process_exception_by_middleware(e, request)
  File "C:\ProgramData\Anaconda3\lib\site-packages\django\core\handlers\base.py", line 126, in _get_response
    response = wrapped_callback(request, *callback_args, **callback_kwargs)
  File "C:\ProgramData\Anaconda3\lib\site-packages\django\views\decorators\csrf.py", line 54, in wrapped_view
    return view_func(*args, **kwargs)
  File "C:\ProgramData\Anaconda3\lib\site-packages\django\views\generic\base.py", line 69, in view
    return self.dispatch(request, *args, **kwargs)
  File "C:\ProgramData\Anaconda3\lib\site-packages\rest_framework\views.py", line 505, in dispatch
    response = self.handle_exception(exc)
  File "C:\ProgramData\Anaconda3\lib\site-packages\rest_framework\views.py", line 465, in handle_exception
    self.raise_uncaught_exception(exc)
  File "C:\ProgramData\Anaconda3\lib\site-packages\rest_framework\views.py", line 476, in raise_uncaught_exception
    raise exc
  File "C:\ProgramData\Anaconda3\lib\site-packages\rest_framework\views.py", line 502, in dispatch
    response = handler(request, *args, **kwargs)
  File "C:\Users\Administrator\PycharmProjects\riskcontrol\aaa\fin_renhang_riskcontrol\akamx\views.py", line 101, in post
    bl_json,xgb_score = bairong.moxing_tz()
  File "C:\Users\Administrator\PycharmProjects\riskcontrol\aaa\fin_renhang_riskcontrol\akamx\bairong.py", line 252, in moxing_tz
    bl_json,xgb_score = self.bar_moing(results_br)
  File "C:\Users\Administrator\PycharmProjects\riskcontrol\aaa\fin_renhang_riskcontrol\akamx\bairong.py", line 124, in bar_moing
    www = lujins.shenfen()
TypeError: 'DataFrame' object is not callable
20/Feb/2020 18:30 [Thread-3: 9856]C:\ProgramData\Anaconda3\lib\site-packages\django\core\servers\basehttp.py:log_message:124 ERROR - "POST /api/ HTTP/1.1" 500 17079
20/Feb/2020 18:30 [Thread-1: 16948]C:\Users\Administrator\PycharmProjects\riskcontrol\aaa\fin_renhang_riskcontrol\akamx\views.py:post:53 INFO - 开始时间4.0123232
20/Feb/2020 18:30 [Thread-1: 16948]C:\Users\Administrator\PycharmProjects\riskcontrol\aaa\fin_renhang_riskcontrol\akamx\views.py:post:78 INFO - requests时间4.0127587
20/Feb/2020 18:30 [Thread-1: 16948]C:\Users\Administrator\PycharmProjects\riskcontrol\aaa\fin_renhang_riskcontrol\akamx\views.py:post:82 INFO - 获取客户的时间4.0130782
20/Feb/2020 18:30 [Thread-1: 16948]C:\Users\Administrator\PycharmProjects\riskcontrol\aaa\fin_renhang_riskcontrol\akamx\views.py:post:90 INFO - 保存客户的时间4.0676548
20/Feb/2020 18:30 [Thread-1: 16948]C:\Users\Administrator\PycharmProjects\riskcontrol\aaa\fin_renhang_riskcontrol\akamx\views.py:post:97 INFO - 获取人行的数据4.0679786
20/Feb/2020 18:30 [Thread-1: 16948]C:\Users\Administrator\PycharmProjects\riskcontrol\aaa\fin_renhang_riskcontrol\akamx\views.py:post:104 INFO - 获取三方数据5.3950844
20/Feb/2020 18:30 [Thread-1: 16948]C:\Users\Administrator\PycharmProjects\riskcontrol\aaa\fin_renhang_riskcontrol\akamx\views.py:post:164 INFO - 输出最终数据6.4900022
20/Feb/2020 18:30 [Thread-1: 16948]C:\Users\Administrator\PycharmProjects\riskcontrol\aaa\fin_renhang_riskcontrol\akamx\views.py:post:174 INFO - 保存数据6.51222
20/Feb/2020 18:30 [Thread-1: 16948]C:\Users\Administrator\PycharmProjects\riskcontrol\aaa\fin_renhang_riskcontrol\akamx\views.py:post:190 INFO - 结束时间6.5126799
20/Feb/2020 18:30 [Thread-1: 16948]C:\Users\Administrator\PycharmProjects\riskcontrol\aaa\fin_renhang_riskcontrol\akamx\views.py:post:192 INFO - 总共用时间是2.5003567
20/Feb/2020 18:30 [Thread-1: 16948]C:\ProgramData\Anaconda3\lib\site-packages\django\core\servers\basehttp.py:log_message:124 INFO - "POST /api/ HTTP/1.1" 200 15
20/Feb/2020 18:30 [Thread-2: 18668]C:\Users\Administrator\PycharmProjects\riskcontrol\aaa\fin_renhang_riskcontrol\akamx\views.py:post:53 INFO - 开始时间7.4599755
20/Feb/2020 18:30 [Thread-2: 18668]C:\Users\Administrator\PycharmProjects\riskcontrol\aaa\fin_renhang_riskcontrol\akamx\views.py:post:78 INFO - requests时间7.4603251
20/Feb/2020 18:30 [Thread-2: 18668]C:\Users\Administrator\PycharmProjects\riskcontrol\aaa\fin_renhang_riskcontrol\akamx\views.py:post:82 INFO - 获取客户的时间7.4607105
20/Feb/2020 18:30 [Thread-2: 18668]C:\Users\Administrator\PycharmProjects\riskcontrol\aaa\fin_renhang_riskcontrol\akamx\views.py:post:90 INFO - 保存客户的时间7.5110915
20/Feb/2020 18:30 [Thread-2: 18668]C:\Users\Administrator\PycharmProjects\riskcontrol\aaa\fin_renhang_riskcontrol\akamx\views.py:post:97 INFO - 获取人行的数据7.5114463
20/Feb/2020 18:30 [Thread-2: 18668]C:\ProgramData\Anaconda3\lib\site-packages\django\core\handlers\exception.py:handle_uncaught_exception:118 ERROR - Internal Server Error: /api/
Traceback (most recent call last):
  File "C:\ProgramData\Anaconda3\lib\site-packages\django\core\handlers\exception.py", line 35, in inner
    response = get_response(request)
  File "C:\ProgramData\Anaconda3\lib\site-packages\django\core\handlers\base.py", line 128, in _get_response
    response = self.process_exception_by_middleware(e, request)
  File "C:\ProgramData\Anaconda3\lib\site-packages\django\core\handlers\base.py", line 126, in _get_response
    response = wrapped_callback(request, *callback_args, **callback_kwargs)
  File "C:\ProgramData\Anaconda3\lib\site-packages\django\views\decorators\csrf.py", line 54, in wrapped_view
    return view_func(*args, **kwargs)
  File "C:\ProgramData\Anaconda3\lib\site-packages\django\views\generic\base.py", line 69, in view
    return self.dispatch(request, *args, **kwargs)
  File "C:\ProgramData\Anaconda3\lib\site-packages\rest_framework\views.py", line 505, in dispatch
    response = self.handle_exception(exc)
  File "C:\ProgramData\Anaconda3\lib\site-packages\rest_framework\views.py", line 465, in handle_exception
    self.raise_uncaught_exception(exc)
  File "C:\ProgramData\Anaconda3\lib\site-packages\rest_framework\views.py", line 476, in raise_uncaught_exception
    raise exc
  File "C:\ProgramData\Anaconda3\lib\site-packages\rest_framework\views.py", line 502, in dispatch
    response = handler(request, *args, **kwargs)
  File "C:\Users\Administrator\PycharmProjects\riskcontrol\aaa\fin_renhang_riskcontrol\akamx\views.py", line 101, in post
    bl_json,xgb_score = bairong.moxing_tz()
  File "C:\Users\Administrator\PycharmProjects\riskcontrol\aaa\fin_renhang_riskcontrol\akamx\bairong.py", line 252, in moxing_tz
    bl_json,xgb_score = self.bar_moing(results_br)
  File "C:\Users\Administrator\PycharmProjects\riskcontrol\aaa\fin_renhang_riskcontrol\akamx\bairong.py", line 124, in bar_moing
    www = lujins.shenfen()
TypeError: 'DataFrame' object is not callable
20/Feb/2020 18:30 [Thread-2: 18668]C:\ProgramData\Anaconda3\lib\site-packages\django\core\servers\basehttp.py:log_message:124 ERROR - "POST /api/ HTTP/1.1" 500 17079
20/Feb/2020 18:31 [Thread-3: 21224]C:\Users\Administrator\PycharmProjects\riskcontrol\aaa\fin_renhang_riskcontrol\akamx\views.py:post:53 INFO - 开始时间9.4856646
20/Feb/2020 18:31 [Thread-3: 21224]C:\Users\Administrator\PycharmProjects\riskcontrol\aaa\fin_renhang_riskcontrol\akamx\views.py:post:78 INFO - requests时间9.4859924
20/Feb/2020 18:31 [Thread-3: 21224]C:\Users\Administrator\PycharmProjects\riskcontrol\aaa\fin_renhang_riskcontrol\akamx\views.py:post:82 INFO - 获取客户的时间9.486333
20/Feb/2020 18:31 [Thread-3: 21224]C:\Users\Administrator\PycharmProjects\riskcontrol\aaa\fin_renhang_riskcontrol\akamx\views.py:post:90 INFO - 保存客户的时间9.542588
20/Feb/2020 18:31 [Thread-3: 21224]C:\Users\Administrator\PycharmProjects\riskcontrol\aaa\fin_renhang_riskcontrol\akamx\views.py:post:97 INFO - 获取人行的数据9.5431818
20/Feb/2020 18:31 [Thread-3: 21224]C:\ProgramData\Anaconda3\lib\site-packages\django\core\handlers\exception.py:handle_uncaught_exception:118 ERROR - Internal Server Error: /api/
Traceback (most recent call last):
  File "C:\ProgramData\Anaconda3\lib\site-packages\django\core\handlers\exception.py", line 35, in inner
    response = get_response(request)
  File "C:\ProgramData\Anaconda3\lib\site-packages\django\core\handlers\base.py", line 128, in _get_response
    response = self.process_exception_by_middleware(e, request)
  File "C:\ProgramData\Anaconda3\lib\site-packages\django\core\handlers\base.py", line 126, in _get_response
    response = wrapped_callback(request, *callback_args, **callback_kwargs)
  File "C:\ProgramData\Anaconda3\lib\site-packages\django\views\decorators\csrf.py", line 54, in wrapped_view
    return view_func(*args, **kwargs)
  File "C:\ProgramData\Anaconda3\lib\site-packages\django\views\generic\base.py", line 69, in view
    return self.dispatch(request, *args, **kwargs)
  File "C:\ProgramData\Anaconda3\lib\site-packages\rest_framework\views.py", line 505, in dispatch
    response = self.handle_exception(exc)
  File "C:\ProgramData\Anaconda3\lib\site-packages\rest_framework\views.py", line 465, in handle_exception
    self.raise_uncaught_exception(exc)
  File "C:\ProgramData\Anaconda3\lib\site-packages\rest_framework\views.py", line 476, in raise_uncaught_exception
    raise exc
  File "C:\ProgramData\Anaconda3\lib\site-packages\rest_framework\views.py", line 502, in dispatch
    response = handler(request, *args, **kwargs)
  File "C:\Users\Administrator\PycharmProjects\riskcontrol\aaa\fin_renhang_riskcontrol\akamx\views.py", line 101, in post
    bl_json,xgb_score = bairong.moxing_tz()
  File "C:\Users\Administrator\PycharmProjects\riskcontrol\aaa\fin_renhang_riskcontrol\akamx\bairong.py", line 252, in moxing_tz
    bl_json,xgb_score = self.bar_moing(results_br)
  File "C:\Users\Administrator\PycharmProjects\riskcontrol\aaa\fin_renhang_riskcontrol\akamx\bairong.py", line 124, in bar_moing
    www = lujins.shenfen()
TypeError: 'DataFrame' object is not callable
20/Feb/2020 18:31 [Thread-3: 21224]C:\ProgramData\Anaconda3\lib\site-packages\django\core\servers\basehttp.py:log_message:124 ERROR - "POST /api/ HTTP/1.1" 500 17079
20/Feb/2020 18:31 [Thread-1: 1924]C:\Users\Administrator\PycharmProjects\riskcontrol\aaa\fin_renhang_riskcontrol\akamx\views.py:post:53 INFO - 开始时间4.5736619
20/Feb/2020 18:31 [Thread-1: 1924]C:\Users\Administrator\PycharmProjects\riskcontrol\aaa\fin_renhang_riskcontrol\akamx\views.py:post:78 INFO - requests时间4.5741073
20/Feb/2020 18:31 [Thread-1: 1924]C:\Users\Administrator\PycharmProjects\riskcontrol\aaa\fin_renhang_riskcontrol\akamx\views.py:post:82 INFO - 获取客户的时间4.5745247
20/Feb/2020 18:31 [Thread-1: 1924]C:\Users\Administrator\PycharmProjects\riskcontrol\aaa\fin_renhang_riskcontrol\akamx\views.py:post:90 INFO - 保存客户的时间4.6196437
20/Feb/2020 18:31 [Thread-1: 1924]C:\Users\Administrator\PycharmProjects\riskcontrol\aaa\fin_renhang_riskcontrol\akamx\views.py:post:97 INFO - 获取人行的数据4.6200646
20/Feb/2020 18:31 [Thread-1: 1924]C:\Users\Administrator\PycharmProjects\riskcontrol\aaa\fin_renhang_riskcontrol\akamx\views.py:post:104 INFO - 获取三方数据5.9375407
20/Feb/2020 18:31 [Thread-1: 1924]C:\Users\Administrator\PycharmProjects\riskcontrol\aaa\fin_renhang_riskcontrol\akamx\views.py:post:164 INFO - 输出最终数据6.9613944
20/Feb/2020 18:31 [Thread-1: 1924]C:\Users\Administrator\PycharmProjects\riskcontrol\aaa\fin_renhang_riskcontrol\akamx\views.py:post:174 INFO - 保存数据6.982686
20/Feb/2020 18:31 [Thread-1: 1924]C:\Users\Administrator\PycharmProjects\riskcontrol\aaa\fin_renhang_riskcontrol\akamx\views.py:post:190 INFO - 结束时间6.9830062
20/Feb/2020 18:31 [Thread-1: 1924]C:\Users\Administrator\PycharmProjects\riskcontrol\aaa\fin_renhang_riskcontrol\akamx\views.py:post:192 INFO - 总共用时间是2.4093443
20/Feb/2020 18:31 [Thread-1: 1924]C:\ProgramData\Anaconda3\lib\site-packages\django\core\servers\basehttp.py:log_message:124 INFO - "POST /api/ HTTP/1.1" 200 15
20/Feb/2020 18:31 [Thread-2: 21224]C:\Users\Administrator\PycharmProjects\riskcontrol\aaa\fin_renhang_riskcontrol\akamx\views.py:post:53 INFO - 开始时间7.8264807
20/Feb/2020 18:31 [Thread-2: 21224]C:\Users\Administrator\PycharmProjects\riskcontrol\aaa\fin_renhang_riskcontrol\akamx\views.py:post:78 INFO - requests时间7.8268267
20/Feb/2020 18:31 [Thread-2: 21224]C:\Users\Administrator\PycharmProjects\riskcontrol\aaa\fin_renhang_riskcontrol\akamx\views.py:post:82 INFO - 获取客户的时间7.8271416
20/Feb/2020 18:31 [Thread-2: 21224]C:\Users\Administrator\PycharmProjects\riskcontrol\aaa\fin_renhang_riskcontrol\akamx\views.py:post:90 INFO - 保存客户的时间7.8766509
20/Feb/2020 18:31 [Thread-2: 21224]C:\Users\Administrator\PycharmProjects\riskcontrol\aaa\fin_renhang_riskcontrol\akamx\views.py:post:97 INFO - 获取人行的数据7.8769713
20/Feb/2020 18:31 [Thread-2: 21224]C:\ProgramData\Anaconda3\lib\site-packages\django\core\handlers\exception.py:handle_uncaught_exception:118 ERROR - Internal Server Error: /api/
Traceback (most recent call last):
  File "C:\ProgramData\Anaconda3\lib\site-packages\django\core\handlers\exception.py", line 35, in inner
    response = get_response(request)
  File "C:\ProgramData\Anaconda3\lib\site-packages\django\core\handlers\base.py", line 128, in _get_response
    response = self.process_exception_by_middleware(e, request)
  File "C:\ProgramData\Anaconda3\lib\site-packages\django\core\handlers\base.py", line 126, in _get_response
    response = wrapped_callback(request, *callback_args, **callback_kwargs)
  File "C:\ProgramData\Anaconda3\lib\site-packages\django\views\decorators\csrf.py", line 54, in wrapped_view
    return view_func(*args, **kwargs)
  File "C:\ProgramData\Anaconda3\lib\site-packages\django\views\generic\base.py", line 69, in view
    return self.dispatch(request, *args, **kwargs)
  File "C:\ProgramData\Anaconda3\lib\site-packages\rest_framework\views.py", line 505, in dispatch
    response = self.handle_exception(exc)
  File "C:\ProgramData\Anaconda3\lib\site-packages\rest_framework\views.py", line 465, in handle_exception
    self.raise_uncaught_exception(exc)
  File "C:\ProgramData\Anaconda3\lib\site-packages\rest_framework\views.py", line 476, in raise_uncaught_exception
    raise exc
  File "C:\ProgramData\Anaconda3\lib\site-packages\rest_framework\views.py", line 502, in dispatch
    response = handler(request, *args, **kwargs)
  File "C:\Users\Administrator\PycharmProjects\riskcontrol\aaa\fin_renhang_riskcontrol\akamx\views.py", line 101, in post
    bl_json,xgb_score = bairong.moxing_tz()
  File "C:\Users\Administrator\PycharmProjects\riskcontrol\aaa\fin_renhang_riskcontrol\akamx\bairong.py", line 252, in moxing_tz
    bl_json,xgb_score = self.bar_moing(results_br)
  File "C:\Users\Administrator\PycharmProjects\riskcontrol\aaa\fin_renhang_riskcontrol\akamx\bairong.py", line 124, in bar_moing
    www = lujins.shenfen()
TypeError: 'DataFrame' object is not callable
20/Feb/2020 18:31 [Thread-2: 21224]C:\ProgramData\Anaconda3\lib\site-packages\django\core\servers\basehttp.py:log_message:124 ERROR - "POST /api/ HTTP/1.1" 500 17079
20/Feb/2020 18:31 [Thread-3: 13372]C:\Users\Administrator\PycharmProjects\riskcontrol\aaa\fin_renhang_riskcontrol\akamx\views.py:post:53 INFO - 开始时间9.8784754
20/Feb/2020 18:31 [Thread-3: 13372]C:\Users\Administrator\PycharmProjects\riskcontrol\aaa\fin_renhang_riskcontrol\akamx\views.py:post:78 INFO - requests时间9.8787954
20/Feb/2020 18:31 [Thread-3: 13372]C:\Users\Administrator\PycharmProjects\riskcontrol\aaa\fin_renhang_riskcontrol\akamx\views.py:post:82 INFO - 获取客户的时间9.8791203
20/Feb/2020 18:31 [Thread-3: 13372]C:\Users\Administrator\PycharmProjects\riskcontrol\aaa\fin_renhang_riskcontrol\akamx\views.py:post:90 INFO - 保存客户的时间9.9258758
20/Feb/2020 18:31 [Thread-3: 13372]C:\Users\Administrator\PycharmProjects\riskcontrol\aaa\fin_renhang_riskcontrol\akamx\views.py:post:97 INFO - 获取人行的数据9.9261975
20/Feb/2020 18:31 [Thread-3: 13372]C:\ProgramData\Anaconda3\lib\site-packages\django\core\handlers\exception.py:handle_uncaught_exception:118 ERROR - Internal Server Error: /api/
Traceback (most recent call last):
  File "C:\ProgramData\Anaconda3\lib\site-packages\django\core\handlers\exception.py", line 35, in inner
    response = get_response(request)
  File "C:\ProgramData\Anaconda3\lib\site-packages\django\core\handlers\base.py", line 128, in _get_response
    response = self.process_exception_by_middleware(e, request)
  File "C:\ProgramData\Anaconda3\lib\site-packages\django\core\handlers\base.py", line 126, in _get_response
    response = wrapped_callback(request, *callback_args, **callback_kwargs)
  File "C:\ProgramData\Anaconda3\lib\site-packages\django\views\decorators\csrf.py", line 54, in wrapped_view
    return view_func(*args, **kwargs)
  File "C:\ProgramData\Anaconda3\lib\site-packages\django\views\generic\base.py", line 69, in view
    return self.dispatch(request, *args, **kwargs)
  File "C:\ProgramData\Anaconda3\lib\site-packages\rest_framework\views.py", line 505, in dispatch
    response = self.handle_exception(exc)
  File "C:\ProgramData\Anaconda3\lib\site-packages\rest_framework\views.py", line 465, in handle_exception
    self.raise_uncaught_exception(exc)
  File "C:\ProgramData\Anaconda3\lib\site-packages\rest_framework\views.py", line 476, in raise_uncaught_exception
    raise exc
  File "C:\ProgramData\Anaconda3\lib\site-packages\rest_framework\views.py", line 502, in dispatch
    response = handler(request, *args, **kwargs)
  File "C:\Users\Administrator\PycharmProjects\riskcontrol\aaa\fin_renhang_riskcontrol\akamx\views.py", line 101, in post
    bl_json,xgb_score = bairong.moxing_tz()
  File "C:\Users\Administrator\PycharmProjects\riskcontrol\aaa\fin_renhang_riskcontrol\akamx\bairong.py", line 252, in moxing_tz
    bl_json,xgb_score = self.bar_moing(results_br)
  File "C:\Users\Administrator\PycharmProjects\riskcontrol\aaa\fin_renhang_riskcontrol\akamx\bairong.py", line 124, in bar_moing
    www = lujins.shenfen()
TypeError: 'DataFrame' object is not callable
20/Feb/2020 18:31 [Thread-3: 13372]C:\ProgramData\Anaconda3\lib\site-packages\django\core\servers\basehttp.py:log_message:124 ERROR - "POST /api/ HTTP/1.1" 500 17079
